Workbook
Name ASFRs: #REF!
Name Births: #REF!
Name CrownCopyright: #REF!
Name DEATHNF: #REF!
Name DeathsF: #REF!
Name DeathsM: #REF!
Name DeathsP: #REF!
Name JanpopF: #REF!
Name janpopm: #REF!
Name janpopp: #REF!
Name jhgkjgjhgjh: #REF!
Name LA: #REF!
Name midpopF: #REF!
Name midpopm: #REF!
Name midpopp: #REF!
Name MigrantsF: #REF!
Name MigrantsM: #REF!
Name MigrantsP: #REF!
Name mxF: #REF!
Name mxM: #REF!
Name mxP: #REF!
Name OtherChangesF: #REF!
Name OtherChangesM: #REF!
Name pensionadjf: #REF!
Name pensionadjm: #REF!
Name ProjBirths: #REF!
Name summaryf: #REF!
Name summarym: #REF!
Name summaryp: #REF!
Name Textline3: #REF!

Sheet Notes
A1: Scottish Local Government Finance Statistics (SLGFS) 2024-25
A2: Revised on 6 February 2026
A4: Background
A5: The 2024-25 Scottish Local Government Finance Statistics (SLGFS) publication provides a comprehensive overview of the financial activity across local authorities in Scotland based on local authorities' audited
A6: accounts. It covers revenue expenditure and income, including local taxation; capital expenditure and financing; reserves and fixed assets; debt and prudential indicators; and pensions.
A8: Full commentary on the key 2024-25 figures is available in the SLGFS 2024-25 publication.
A10: Data Interpretation
A11: Please note the following information when using data provided in this file:
A12: • Scotland figures cover financial activity across all 32 councils, 10 Valuation Joint Boards (VJBs), 7 Regional Transport Partnerships (RTPs) and the Tay Road Bridge Joint Authority.
A13: • Figures are presented on a funding basis and so have been adjusted to remove certain accounting transactions that have been charged to services, such as depreciation and pension costs.
A14: • All years refer to the relevant financial year running 1 April to 31 March.
A15: • Figures within tables / charts may not sum to the total exactly due to rounding.
... A51: For enquiries about this data, please email lgfstats@gov.scot.

Sheet Contents
A1: Contents
A2: This worksheet contains one table.
A4: Tab Name | B4: Table Name
A5: Table 2.1 | B5: Net Revenue Expenditure on Services in 2024-25, £ millions
A6: Chart 2.1 | B6: Net Revenue Expenditure in 2024-25 by Service, £ millions
A7: Table 2.2 | B7: Net Revenue Expenditure from 2020-21 to 2024-25 by Service, £ millions
A8: Chart 2.2 | B8: General Fund Net Revenue Expenditure in 2024-25 by Council, £ per person
A9: Table 2.3 | B9: Gross Service Expenditure from 2020-21 to 2024-25 by Expenditure Type, £ millions
A10: Chart 2.3 | B10: Gross Service Expenditure in 2024-25 by Service and Expenditure Type, £ millions
A11: Table 2.4 | B11: Gross Service Income from 2020-21 to 2024-25 by Income Type, £ millions
A12: Table 2.4a | B12: Customer and Client Receipts from 2020-21 to 2024-25 by Service, £ millions
A13: Chart 2.4 | B13: Gross Service Income in 2024-25 by Service and Income Type, £ millions
A14: Chart 2.5 | B14: Service Expenditure met by Service Income in 2024-25 by Service, £ millions
A15: Table 2.5 | B15: Other Expenditure and Income in 2024-25, £ millions
... A76: Annex C | B76: Calculation of General Revenue Grant for SLGFS 2024-25, £000s.

Sheet Table 2.1
A1: Table 2.1: Net Revenue Expenditure on Services in 2024-25, £ millions
A2: This worksheet contains one table.
A3: Source: LFR 00
A4: Return to Contents
A6: Category | B6: General Fund | C6: HRA | D6: Total
A7: Gross Service Expenditure | B7: 24829.204 | C7: 1022.67 | D7: 25851.874
A8: Gross Service Income | B8: 9404.116 | C8: 1561.007 | D8: 10965.123
A9: Net Revenue Expenditure | B9: 15425.088 | C9: -538.337 | D9: 14886.751

Sheet Chart 2.1
A1: Chart 2.1: Net Revenue Expenditure in 2024-25 by Service, £ millions
A2: This worksheet contains one table and one chart.
A3: Source: LFR 00
A4: Return to Contents
A6: Service | B6: 2024-25
A7: Education Services | B7: 7777.996
A8: Social Work Services | B8: 4873.13
A9: Environmental Services | B9: 798.165
A10: Culture and Related Services | B10: 650.742
A11: Roads and Transport | B11: 440.749
A12: Central Services | B12: 400.565
A13: Non-HRA Housing | B13: 327.904
A14: Building, Planning & Development | B14: 208.046
A15: Trading Services | B15: -52.209
A16: HRA | B16: -538.337
A19: 05/02/2026 Corrected values for Culture and Relates Services, etc.

Sheet Table 2.2
A1: Table 2.2: Net Revenue Expenditure from 2020-21 to 2024-25 by Service, £ millions
A2: This worksheet contains one table.
A3: Source: LFR 00
A4: Return to Contents
A6: Service | B6: 2020-21 | C6: 2021-22 | D6: 2022-23 | E6: 2023-24 | F6: 2024-25 | G6: % change between 2023-24 & 2024-25
A7: Education | B7: 5524.371 | C7: 5867.375 | D7: 6471.278 | E7: 6960.284 | F7: 7777.996 | G7: 0.11748256
A8: Culture and Related Services | B8: 582.321 | C8: 592.438 | D8: 650.985 | E8: 675.069 | F8: 650.742 | G8: -0.036036316
A9: Social Work | B9: 3539.628 | C9: 3817.918 | D9: 4290.939 | E9: 4604.52 | F9: 4873.129 | G9: 0.058335939
A10: Roads and Transport | B10: 457.509 | C10: 404.171 | D10: 436.92 | E10: 454.477 | F10: 440.749 | G10: -0.030206149
A11: Environmental Services | B11: 725.918 | C11: 719.485 | D11: 753.804 | E11: 810.547 | F11: 798.165 | G11: -0.015276104
A12: Building, Planning & Development | B12: 218.665 | C12: 250.379 | D12: 246.488 | E12: 262.648 | F12: 208.046 | G12: -0.20789041
A13: Central Services | B13: 386.647 | C13: 362.817 | D13: 339.967 | E13: 691.911 | F13: 400.565 | G13: -0.42107439
A14: Non-HRA Housing | B14: 272.485 | C14: 290.774 | D14: 321.849 | E14: 338.919 | F14: 327.904 | G14: -0.032500391
A15: Trading Services | B15: -28.644 | C15: -28.512 | D15: -24.772 | E15: -40.61 | F15: -52.209 | G15: 0.28561931
A16: General Fund Net Expenditure | B16: 11678.9 | C16: 12276.845 | D16: 13487.458 | E16: 14757.765 | F16: 15425.087 | G16: 0.045218365
A17: Housing Revenue Account (HRA) | B17: -571.342 | C17: -526.652 | D17: -537.761 | E17: -457.319 | F17: -538.337 | G17: 0.17715861
A18: Total Net Revenue Expenditure | B18: 11107.558 | C18: 11750.193 | D18: 12949.697 | E18: 14300.446 | F18: 14886.75 | G18: 0.040999001

Sheet Chart 2.2
A1: Chart 2.2: General Fund Net Revenue Expenditure in 2024-25 by Council, £ per person
A2: This worksheet contains one table and one chart.
A3: Source: LFR 00, National Records of Scotland Mid-2024 population estimates.
A4: Return to Contents
A6: Local Authority | B6: Net Revenue Expenditure, £ thousands | C6: Population | D6: Net Revenue Expenditure, £ per person
A7: Shetland Islands | B7: 123088 | C7: 23190 | D7: 5307.8051
A8: Orkney Islands | B8: 108262 | C8: 22020 | D8: 4916.5304
A9: Na h-Eileanan Siar | B9: 116976 | C9: 26020 | D9: 4495.6188
A10: Argyll & Bute | B10: 297391 | C10: 87690 | D10: 3391.3901
A11: North Ayrshire | B11: 406386 | C11: 134010 | D11: 3032.505
A12: Dumfries & Galloway | B12: 442195 | C12: 145860 | D12: 3031.6399
A13: West Dunbartonshire | B13: 268983 | C13: 89120 | D13: 3018.2114
A14: Highland | B14: 714122 | C14: 237290 | D14: 3009.4905
A15: Midlothian | B15: 296847 | C15: 99880 | D15: 2972.0364
A16: Stirling | B16: 278517 | C16: 94210 | D16: 2956.3422
A17: Inverclyde | B17: 232103 | C17: 78880 | D17: 2942.4823
A18: East Renfrewshire | B18: 293687 | C18: 99830 | D18: 2941.8712
... A39: Aberdeen City | B39: 533890 | C39: 231780 | D39: 2303.4343

Sheet Table 2.3
A1: Table 2.3: Gross Service Expenditure from 2020-21 to 2024-25 by Expenditure Type, £ millions
A2: This worksheet contains one table.
A3: Source: LFR 00
A4: Return to Contents
A6: Expenditure Type | B6: 2020-21 | C6: 2021-22 | D6: 2022-23 | E6: 2023-24 | F6: 2024-25 | G6: % change between 2023-24 & 2024-25
A7: Employee Costs | B7: 8191.302 | C7: 8611.415 | D7: 9304.812 | E7: 10341.491 | F7: 10210.515 | G7: -0.012665098
A8: Operating Costs | B8: 8065.626 | C8: 8400.028 | D8: 9045.557 | E8: 9705.862 | F8: 10164.305 | G8: 0.04723362
A9: Transfer Payments | B9: 4723.988 | C9: 5025.592 | D9: 5431.787 | E9: 5598.822 | F9: 5907.459 | G9: 0.055125346
A10: Support Services | B10: 742.8 | C10: 785.187 | D10: 831.762 | E10: 898.431 | F10: 909.645 | G10: 0.01248176
A11: Adjustment for Intra / Inter Authority Transfers | B11: -1252.824 | C11: -1222.938 | D11: -1223.738 | E11: -1312.929 | F11: -1340.05 | G11: 0.020656867
A12: Gross Service Expenditure | B12: 20470.892 | C12: 21599.284 | D12: 23390.18 | E12: 25231.677 | F12: 25851.874 | G12: 0.024580094

Sheet Chart 2.3
A1: Chart 2.3: Gross Service Expenditure in 2024-25 by Service and Expenditure Type, £ millions
A2: This worksheet contains one table and one chart.
A3: Please note that 'Other' consists of Building, Planning & Development Services, Central Services and Trading Services.
A4: Source: LFR 00
A5: Return to Contents
A7: Service | B7: Employee Costs | C7: Operating Costs | D7: Transfer Payments | E7: Support Services | F7: Intra / Inter Authority Transfer Adjustment | G7: Gross Expenditure
A8: Social Work | B8: 2000.284 | C8: 3919.322 | D8: 4160.602 | E8: 195.225 | F8: -44.667 | G8: 10230.766
A9: Education | B9: 5846.502 | C9: 2144.389 | D9: 77.18 | E9: 288.063 | F9: -100.915 | G9: 8255.219
A10: Non-HRA Housing | B10: 188.26 | C10: 536.784 | D10: 1495.944 | E10: 44.708 | F10: -112.461 | G10: 2153.235
A11: Other | B11: 870.082 | C11: 1062.557 | D11: 123.329 | E11: 178.952 | F11: -699.862 | G11: 1535.058
A12: HRA | B12: 226.348 | C12: 738.12 | D12: 14.716 | E12: 60.323 | F12: -16.837 | G12: 1022.67
A13: Environmental Services | B13: 474.261 | C13: 551.633 | D13: 1.243 | E13: 57.216 | F13: -84.749 | G13: 999.604
A14: Roads & Transport | B14: 311.341 | C14: 717.615 | D14: 21.758 | E14: 47.883 | F14: -232.647 | G14: 865.95
A15: Culture & Related Services | B15: 293.437 | C15: 493.885 | D15: 12.687 | E15: 37.275 | F15: -47.912 | G15: 789.372
A16: Total General Fund and HRA | B16: 10210.515 | C16: 10164.305 | D16: 5907.459 | E16: 909.645 | F16: -1340.05 | G16: 25851.874

Sheet Table 2.4
A1: Table 2.4: Gross Service Income from 2020-21 to 2024-25 by Income Type, £ millions
A2: This worksheet contains one table.
A3: Please note that 'Government Grants' relates to service specific government grants, including those paid in relation to the Covid-19 pandemic. This figure does not include GRG.
A4: Source: LFR 00
A5: Return to Contents
A7: Income Type | B7: 2020-21 | C7: 2021-22 | D7: 2022-23 | E7: 2023-24 | F7: 2024-25 | G7: % change between 2023-24 & 2024-25
A8: Government Grants | B8: 2866.091 | C8: 2884.467 | D8: 2856.506 | E8: 2800.956 | F8: 2270.162 | G8: -0.18950458
A9: Other Grants, Reimbursements and Contributions | B9: 4003.177 | C9: 4249.253 | D9: 4676.437 | E9: 4945.833 | F9: 5244.825 | G9: 0.060453315
A10: Customer and Client Receipts | B10: 2494.066 | C10: 2715.371 | D10: 2907.54 | E10: 3184.442 | F10: 3450.136 | G10: 0.083435026
A11: Gross Service Income | B11: 9363.334 | C11: 9849.091 | D11: 10440.483 | E11: 10931.231 | F11: 10965.123 | G11: 0.0031004742

Sheet Table 2.4a
A1: Table 2.4a: Customer and Client Receipts from 2020-21 to 2024-25 by Service, £ millions
A2: This worksheet contains one table.
A3: Source: LFR 00
A4: Return to Contents
A6: Service | B6: ='Table 2.4'!B7 -> 2020-21 | C6: ='Table 2.4'!C7 -> 2021-22 | D6: ='Table 2.4'!D7 -> 2022-23 | E6: ='Table 2.4'!E7 -> 2023-24 | F6: ='Table 2.4'!F7 -> 2024-25
A7: Education | B7: 47.448 | C7: 73.465 | D7: 81.855 | E7: 87.828 | F7: 106.496
A8: Culture & Related Services | B8: 28.43 | C8: 70.142 | D8: 99.984 | E8: 117.645 | F8: 106.764
A9: Social Work | B9: 268.147 | C9: 278.985 | D9: 308.551 | E9: 338.339 | F9: 367.552
A10: Roads & Transport | B10: 115.253 | C10: 159.006 | D10: 185.861 | E10: 228.744 | F10: 279.499
A11: Environmental Services | B11: 113.673 | C11: 145.701 | D11: 155.213 | E11: 171.437 | F11: 184.066
A12: Building, Planning & Development | B12: 124.63 | C12: 148.524 | D12: 164.604 | E12: 163.2 | F12: 176.959
A13: Central Services | B13: 188.661 | C13: 210.285 | D13: 238.149 | E13: 286.76 | F13: 273.296
A14: Non-HRA Housing | B14: 179.553 | C14: 191.218 | D14: 203.348 | E14: 243.54 | F14: 291.478
A15: Trading Services | B15: 120.117 | C15: 119.233 | D15: 123.746 | E15: 125.77 | F15: 126.075
A16: Total General Fund | B16: 1185.912 | C16: 1396.559 | D16: 1561.311 | E16: 1763.263 | F16: 1912.185
A17: HRA | B17: 1308.154 | C17: 1318.812 | D17: 1346.229 | E17: 1421.179 | F17: 1537.951
A18: Total General Fund and HRA | B18: 2494.066 | C18: 2715.371 | D18: 2907.54 | E18: 3184.442 | F18: 3450.136

Sheet Chart 2.4
A1: Chart 2.4: Gross Service Income in 2024-25 by Service and Income Type, £ millions
A2: This worksheet contains one table and one chart. Please note the following:
A3: 'Government Grants' relates to service specific government grants, including those paid in relation to the Covid-19 pandemic. This figure does not include GRG.
A4: The 'Other' category consists of Building, Planning & Development Services, Central Services and Trading Services.
A5: Source: LFR 00
A6: Return to Contents
A8: Service | B8: Government Grants | C8: Other Grants, Reimbursements & Contributions | D8: Customer and Client Receipts | E8: Gross Income
A9: Social Work Services | B9: 201.049 | C9: 4789.035 | D9: 367.552 | E9: 5357.636
A10: Non-HRA Housing | B10: 1322.114 | C10: 211.739 | D10: 291.478 | E10: 1825.331
A11: HRA | B11: 6.886 | C11: 16.17 | D11: 1537.951 | E11: 1561.007
A12: Other | B12: 301.533 | C12: 100.793 | D12: 576.33 | E12: 978.656
A13: Education Services | B13: 297.62 | C13: 73.107 | D13: 106.496 | E13: 477.223
A14: Roads and Transport | B14: 119.233 | C14: 26.469 | D14: 279.499 | E14: 425.201
A15: Environmental Services | B15: 7.784 | C15: 9.589 | D15: 184.066 | E15: 201.439
A16: Culture and Related Services | B16: 13.943 | C16: 17.923 | D16: 106.764 | E16: 138.63

Sheet Chart 2.5
A1: Chart 2.5: Service Expenditure met by Service Income in 2024-25 by Service, £ millions
A2: This worksheet contains one table and one chart.
A3: Source: LFR 00
A4: Return to Contents
A6: Service | B6: Gross Service Income | C6: Gross Service Expenditure | D6: Service Expenditure met by Service Income | E6: Service Expenditure NOT met by Service Income | F6: Service Income in excess of Service Expenditure
A7: Social Work Services | B7: 5357.636 | C7: 10230.766 | D7: 5357.636 | E7: 4873.13 | F7: 0
A8: Education Services | B8: 477.223 | C8: 8255.219 | D8: 477.223 | E8: 7777.996 | F8: 0
A9: Non-HRA Housing | B9: 1825.331 | C9: 2153.235 | D9: 1825.331 | E9: 327.904 | F9: 0
A10: HRA | B10: 1561.007 | C10: 1022.67 | D10: 1022.67 | E10: 0 | F10: 538.337
A11: Environmental Services | B11: 201.439 | C11: 999.604 | D11: 201.439 | E11: 798.165 | F11: 0
A12: Roads and Transport | B12: 425.201 | C12: 865.95 | D12: 425.201 | E12: 440.749 | F12: 0
A13: Culture and Related Services | B13: 138.63 | C13: 789.372 | D13: 138.63 | E13: 650.742 | F13: 0
A14: Central Services | B14: 348.073 | C14: 748.638 | D14: 348.073 | E14: 400.565 | F14: 0
A15: Building, Planning & Development | B15: 503.149 | C15: 711.195 | D15: 503.149 | E15: 208.046 | F15: 0
A16: Trading Services | B16: 127.434 | C16: 75.225 | D16: 75.225 | E16: 0 | F16: 52.209
A17: Total General Fund and HRA | B17: 10965.123 | C17: 25851.874 | D17: 10374.577 | E17: 15477.297 | F17: 590.546

Sheet Table 2.5
A1: Table 2.5: Other Expenditure and Income in 2024-25, £ millions
A2: This worksheet contains one table. Please note the following:
A3: Income figures are presented as negatives in this table to distinguish them from expenditure figures.
A4: 'Interest Receivable and Similar Income' includes losses arising from derecognition of financial assets and recognition of credit losses on financial assets.
A5: 'Statutory Repayment of Debt' includes repayments relating to lending to other statutory bodies and so will differ to the repayment figures shown in Chapter 5.
A6: Source: LFR A0
A7: Return to Contents
A9: Expenditure / Income Type | B9: General Fund | C9: HRA | D9: Total
A10: Interest Payable and Similar Charges | B10: 927.611 | C10: 228.653 | D10: 1156.264
A11: Interest Receivable and Similar Income | B11: -163.704 | C11: -11.199 | D11: -174.903
A12: Statutory Repayment of Debt | B12: 430.573 | C12: 160.643 | D12: 591.216
A13: Capital Expenditure Funded from GF / HRA / Harbour only | B13: 113.292 | C13: 159.094 | D13: 272.386
A14: Surplus (-) or Deficit (+) from Trading Operations | B14: -0.418 | C14: 0 | D14: -0.418
A15: Other Operating Expenditure | B15: -1.066 | C15: 0.238 | D15: -0.828
A16: Total Other Expenditure and Income | B16: 1306.288 | C16: 537.429 | D16: 1843.717

Sheet Chart 2.6
A1: Chart 2.6: General Funding in 2024-25 by Source, £ millions
A2: This worksheet contains one table.
A3: Please note that 'Other Funding' includes government grants paid to joint boards, income received through NDR TIF and NDRIS schemes plus capital to revenue transfers.
A4: Source: LFR A0
A5: Return to Contents
A7: General Funding Source | B7: 2024-25
A8: General Revenue Grant (GRG) | B8: 10337.276
A9: NDR Distributable Amount | B9: 3067.607
A10: Council Tax | B10: 2996.849
A11: Other Funding | B11: 10.7
A12: Total General Funding | B12: 16412.432

Sheet Table 2.6
A1: Table 2.6: General Funding from 2020-21 to 2024-25 by Source, £ millions
A2: This worksheet contains one table. Please note the following:
A3: GRG figures for 2018-19 and 2019-20 differ from the Finance Circular allocation due to £10m for Teacher's Pay which was paid as part of the 2019-20 settlement but recorded by local authorities as income in 2018-19.
A4: The 2020-21, 2021-22, and 2022-23 GRG figure differ from the Finance Circular allocation due to the exclusion of amounts for agency grants paid to local authorities via GRG. See the Table in Annex C for details for 2024-25.
A5: 'Other Funding' includes government grants paid to joint boards, income received through NDR TIF and NDRIS schemes plus capital to revenue transfers.
A6: Source: LFR A0
A7: Return to Contents
A9: General Funding Source | B9: 2020-21 | C9: 2021-22 | D9: 2022-23 | E9: 2023-24 | F9: 2024-25 | G9: % change between 2023-24 & 2024-25
A10: General Revenue Grant (GRG) | B10: 9307.767 | C10: 9013.8953 | D10: 8672.1278 | E10: 8920.158 | F10: 10337.276 | G10: 0.15886692
A11: NDR Distributable Amount | B11: 1867.958 | C11: 2089.923 | D11: 2765.289 | E11: 3045.016 | F11: 3067.607 | G11: 0.0074190086
A12: Council Tax | B12: 2581.475 | C12: 2640.123 | D12: 2766.633 | E12: 2930.953 | F12: 2996.849 | G12: 0.02248279
A13: Other Funding | B13: 76.535 | C13: 43.705 | D13: 29.539 | E13: 87.299 | F13: 10.7 | G13: -0.87743273
A14: Total General Funding | B14: 13833.735 | C14: 13787.646 | D14: 14233.589 | E14: 14983.426 | F14: 16412.432 | G14: 0.095372447

Sheet Table 2.7
A1: Table 2.7: Valuation Range and Ratios by Council Tax Band
A2: This worksheet contains one table. Please note the following:
A3: “n/a” indicates where a total value is not applicable.
A4: The ratios quoted applied from 2017-18 onwards.
A5: Source: CTaxbase
A6: Return to Contents
A8: Band | B8: Valuation Band Ranges as at 1 April 1991 | C8: Ratio to Band D | D8: No. of Chargeable Dwellings as at September 2024 | E8: Proportion of Chargeable dwellings
A9: Band A | B9: Under £27,000 | C9: 6/9 | D9: 497867 | E9: =D9/$D$17 -> 0.19130005
A10: Band B | B10: £27,001 to £35,000 | C10: 7/9 | D10: 581576 | E10: =D10/$D$17 -> 0.22346434
A11: Band C | B11: £35,001 to £45,000 | C11: 8/9 | D11: 423304 | E11: =D11/$D$17 -> 0.16265002
A12: Band D | B12: £45,001 to £58,000 | C12: 9/9 | D12: 365001 | E12: =D12/$D$17 -> 0.14024772
A13: Band E | B13: £58,001 to £80,000 | C13: 473/360 | D13: 362354 | E13: =D13/$D$17 -> 0.13923064
A14: Band F | B14: £80,001 to £106,000 | C14: 585/360 | D14: 217954 | E14: =D14/$D$17 -> 0.083746487
A15: Band G | B15: £106,001 to £212,000 | C15: 705/360 | D15: 140162 | E15: =D15/$D$17 -> 0.053855745
A16: Band H | B16: Over £212,000 | C16: 882/360 | D16: 14327 | E16: =D16/$D$17 -> 0.0055049961
A17: Total | D17: =SUM(D9:D16) -> 2602545 | E17: 1

Sheet Chart 2.7
A1: Chart 2.7: Council Tax Potential Yield in 2024-25, £ millions
A2: This worksheet contains one table and one chart. Council Tax Potential Yield refers to the Council Tax yield if all dwellings paid the full rate for their relevant Band and Local Authority.
A3: Source: CTaxbase and CTRR
A4: Return to Contents
A6: Category | B6: Band A | C6: Band B | D6: Band C | E6: Band D | F6: Band E | G6: Band F | H6: Band G | I6: Band H | J6: Total
A7: Council Tax Billed (Estimate) | B7: 257.7848 | C7: 430.48582 | D7: 397.1178 | E7: 429.1025 | F7: 596.75538 | G7: 460.81448 | H7: 363.02186 | I7: 46.584773 | J7: 2981.6674
A8: Council Tax Reduction (CTR) | B8: 129.88025 | C8: 119.9954 | D8: 71.744622 | E8: 36.055503 | F8: 21.087467 | G8: 7.9794455 | H8: 3.4014415 | I8: 0.15853198 | J8: 390.30266
A9: Reduction in yield due to Single Person Discount (25%) | B9: 70.924462 | C9: 79.126669 | D9: 56.938359 | E9: 44.96712 | F9: 44.514751 | G9: 24.465192 | H9: 15.504144 | I9: 1.5361088 | J9: 337.97681
A10: Reduction in yield due to exempt dwellings (no CT) | B10: 50.311448 | C10: 33.097041 | D10: 25.084836 | E10: 21.435691 | F10: 25.456742 | G10: 13.560869 | H10: 7.0888758 | I10: 2.0040166 | J10: 178.03952
A11: Other Discounts | B11: 12.447653 | C11: 12.488857 | D11: 10.63473 | E11: 9.6136652 | F11: 11.48667 | G11: 7.1103813 | H11: 5.7295465 | I11: 1.6760829 | J11: 71.187586
A12: Gross Potential Council Tax | B12: 521.34861 | C12: 675.19379 | D12: 561.52035 | E12: 541.17448 | F12: 699.30101 | G12: 513.93037 | H12: 394.74587 | I12: 51.959513 | J12: 3959.174

Sheet Table 2.8
A1: Table 2.8: Council Tax Income after CTR in 2024-25 by Local Authority, £ thousands
A2: This worksheet contains one table containing figures that relate to income collected in 2024-25, which can include amounts that were billed in previous years.
A3: Source: LFR A0
A4: Return to Contents
A6: Local Authority | B6: Council Tax Income after CTR
A7: Aberdeen City | B7: 143678
A8: Aberdeenshire | B8: 170446
A9: Angus | B9: 58344
A10: Argyll & Bute | B10: 66948
A11: City of Edinburgh | B11: 330188
A12: Clackmannanshire | B12: 26005
A13: Dumfries & Galloway | B13: 79364
A14: Dundee City | B14: 66343
A15: East Ayrshire | B15: 59317
A16: East Dunbartonshire | B16: 72555
A17: East Lothian | B17: 72867
A18: East Renfrewshire | B18: 63328
... A39: Scotland | B39: 2996849

Sheet Table 2.9
A1: Table 2.9: Total Number of Dwellings from 2020-21 to 2024-25
A2: This worksheet contains one table.
A3: Source: CTaxbase
A4: Return to Contents
A6: Financial Year | B6: Total Dwellings | C6: Exempt Dwellings | D6: Chargeable Dwellings
A7: 2020-21 | B7: 2653732 | C7: 130845 | D7: 2522887
A8: 2021-22 | B8: 2674729 | C8: 134096 | D8: 2540633
A9: 2022-23 | B9: 2699040 | C9: 136683 | D9: 2562357
A10: 2023-24 | B10: 2720920 | C10: 139192 | D10: 2581728
A11: 2024-25 | B11: 2740973 | C11: 138428 | D11: 2602545

Sheet Chart 2.8
A1: Chart 2.8: Proportion of Chargeable Dwellings at September 2024 by Local Authority and Council Tax Band
A2: This worksheet contains one table and one chart.
A3: Source: CTaxbase
A4: Return to Contents
A6: Local Authority | B6: Number in Bands A to B | C6: Number in Bands C to D | D6: Number in Bands E to H | E6: Total in Bands A to H | F6: Proportion in Bands A to B | G6: Proportion in Bands C to D | H6: Proportion in Bands E to H | I6: Proportion in Bands A to D
A7: East Renfrewshire | B7: 6207 | C7: 10834 | D7: 23040 | E7: 40081 | F7: 0.15486141 | G7: 0.27030264 | H7: 0.57483596 | I7: 0.42516404
A8: East Dunbartonshire | B8: 4567 | C8: 16959 | D8: 25680 | E8: 47206 | F8: 0.096746176 | G8: 0.35925518 | H8: 0.54399864 | I8: 0.45600136
A9: Stirling | B9: 13649 | C9: 9173 | D9: 18049 | E9: 40871 | F9: 0.33395317 | G9: 0.22443787 | H9: 0.44160896 | I9: 0.55839104
A10: Aberdeenshire | B10: 34748 | C10: 32538 | D10: 52056 | E10: 119342 | F10: 0.29116321 | G10: 0.272645 | H10: 0.43619178 | I10: 0.56380822
A11: City of Edinburgh | B11: 65789 | C11: 84516 | D11: 95325 | E11: 245630 | F11: 0.2678378 | G11: 0.34407849 | H11: 0.3880837 | I11: 0.6119163
A12: East Lothian | B12: 10286 | C12: 22207 | D12: 19525 | E12: 52018 | F12: 0.19773924 | G12: 0.42690992 | H12: 0.37535084 | I12: 0.62464916
A13: Perth & Kinross | B13: 22569 | C13: 24187 | D13: 27547 | E13: 74303 | F13: 0.30374278 | G13: 0.32551849 | H13: 0.37073873 | I13: 0.62926127
A14: South Ayrshire | B14: 19060 | C14: 17282 | D14: 18779 | E14: 55121 | F14: 0.34578473 | G14: 0.31352842 | H14: 0.34068685 | I14: 0.65931315
A15: Argyll & Bute | B15: 16854 | C15: 15326 | D15: 15342 | E15: 47522 | F15: 0.35465679 | G15: 0.32250326 | H15: 0.32283995 | I15: 0.67716005
A16: Midlothian | B16: 13230 | C16: 17038 | D16: 13372 | E16: 43640 | F16: 0.30316224 | G16: 0.39042163 | H16: 0.30641613 | I16: 0.69358387
A17: Aberdeen City | B17: 46827 | C17: 35072 | D17: 33683 | E17: 115582 | F17: 0.40514094 | G17: 0.30343825 | H17: 0.29142081 | I17: 0.70857919
A18: Highland | B18: 41033 | C18: 44697 | D18: 35055 | E18: 120785 | F18: 0.33971934 | G18: 0.37005423 | H18: 0.29022644 | I18: 0.70977356
... A39: Na h-Eileanan Siar | B39: 8355 | C39: 4638 | D39: 1609 | E39: 14602 | F39: 0.57218189 | G39: 0.31762772 | H39: 0.11019038 | I39: 0.88980962

Sheet Chart 2.9
A1: Chart 2.9: Band D Council Tax Rate in 2024-25 by Local Authority
A2: This worksheet contains one table and one chart.
A3: Source: CTAS
A4: Return to Contents
A6: Local Authority | B6: Band D Rate
A7: Shetland Islands | B7: 1260.61
A8: Na h-Eileanan Siar | B8: 1290.75
A9: South Lanarkshire | B9: 1300.81
A10: Angus | B10: 1316.68
A11: North Lanarkshire | B11: 1320.78
A12: Dumfries & Galloway | B12: 1334.85
A13: Scottish Borders | B13: 1356.11
A14: Falkirk | B14: 1363.82
A15: Orkney Islands | B15: 1369.21
A16: Fife | B16: 1385.18
A17: West Lothian | B17: 1390.96
A18: Aberdeenshire | B18: 1393.42
... A39: Inverclyde | B39: 1547.01

Sheet Table 2.10
A1: Table 2.10: Average Council Tax Bill per Dwelling from 2020-21 to 2024-25
A2: This worksheet contains one table. Please note that minor changes between years where Council Tax was frozen are due to a number of factors,
A3: including the distribution of dwellings across bands; discounts and exemptions; new construction and removal of demolished housing from the roll.
A4: Source: CTAS, CTaxbase and LFR 12
A5: Return to Contents
A7: Financial Year | B7: Before CTR | C7: After CTR
A8: 2020-21 | B8: 1201 | C8: 1053.1157
A9: 2021-22 | B9: 1198.2209 | C9: 1057.2642
A10: 2022-23 | B10: 1238.0307 | C10: 1095.6665
A11: 2023-24 | B11: 1301.8944 | C11: 1152
A12: 2024-25 | B12: 1309.7148 | C12: 1160

Sheet Table 2.11
A1: Table 2.11: CTR Funding and Reduction in Liability in 2024-25 by Local Authority, £ thousands
A2: This worksheet contains one table.
A3: Source: CTR Extracts and LFR 12
A4: Return to Contents
A6: Local Authority | B6: CTR Funding from SG | C6: Final total reduction in liability
A7: Aberdeen City | B7: 11057.056 | C7: 12628
A8: Aberdeenshire | B8: 8955.2779 | C8: 9749
A9: Angus | B9: 5531.9374 | C9: 6049
A10: Argyll & Bute | B10: 5453.5022 | C10: 5953
A11: City of Edinburgh | B11: 25522.279 | C11: 27395
A12: Clackmannanshire | B12: 3734.2412 | C12: 4190
A13: Dumfries & Galloway | B13: 9655.5846 | C13: 10807
A14: Dundee City | B14: 12435.444 | C14: 13617
A15: East Ayrshire | B15: 9454.1685 | C15: 10354
A16: East Dunbartonshire | B16: 4843.1298 | C16: 5347
A17: East Lothian | B17: 5559.0628 | C17: 6270
A18: East Renfrewshire | B18: 4052.8809 | C18: 4400
... A39: Scotland | B39: 351000 | C39: 389010

Sheet Table 2.12
A1: Table 2.12: Council Tax Discounts, Exemptions, Reductions and Increases
A2: This worksheet contains one table, which contains blank cells due to subheadings in Rows 7, 13 and 16.
A3: Please note that in 2013-14, local authorities gained the discretionary power to remove the discount for Second Homes / Long Term Empty, or set a Council Tax increase of 100% on 'Long Term Empty - More than 12 months' properties.
A4: Return to Contents
A6: Type of Support | B6: Typical dwellings that are eligible | C6: Reduction in liability
A7: Discounts
A8: Single Person Discount | B8: Chargeable dwellings in which there is only one resident or only one resident who is not disregarded | C8: 25% discount
A9: Second Homes | B9: Chargeable dwellings which are no one's sole or main residence, but are furnished and lived in for at least 25 days during any 12 month period. | C9: Up to 50% discount or an increase of up to 100% from April 2024 (actual change depends on local authority policy)
A10: Short Term Empty - Less than 12 months (or 24 months for properties for sale or let) | B10: Empty properties not meeting the criteria of a second home, or subject to a separate exemption. | C10: 10 - 50% discount (actual change depends on local authority policy)
A11: Long Term Empty - More than 12 months (or 24 months for properties for sale or let) | B11: Empty properties not meeting the criteria of a second home, or subject to a separate exemption. | C11: Up to 50% discount or an increase of up to 100% (actual change depends on local authority policy)
A12: Occupied entirely by disregarded adults | B12: Chargeable dwellings occupied entirely by residents who are disregarded for a discount. | C12: 50% discount
A13: Exemptions
A14: Occupied | B14: Dwellings occupied solely by any combination of students, care leavers, those with a severe mental impairment, school leavers or persons under the age of 18. | C14: 100% reduction
A15: Unoccupied | B15: Dwellings which are; empty and unfurnished for less than 6 months or empty and under repair for less than 12 months. Dwellings which are empty because their former residents have moved out for the purposes of receiving personal care by reason of old age, disablement or illness. | C15: 100% reduction
A16: Reductions
A17: Disability reduction | B17: Homes that have been adapted for a disabled person. | C17: One CT Band, for example an eligible Band D property would be charged the Band C rate. Eligible Band A properties are charged 5/9 of the Band D rate.
A18: Council Tax Reduction (Passported) | B18: In receipt of Pension Credit (Guarantee), Jobseeker's Allowance (income based), Employment and Support Allowance (income related) or Income Support. | C18: 100% reduction
A19: Council Tax Reduction (Not passported) | B19: Low income household. Universal Credit (UC) replaces the above benefits that currently passport recipients to full CTR, with the exception of Pension Credit. UC also replaces Working Tax Credits, Child Tax Credits and Housing Benefit. UC is not a passporting benefit. | C19: Up to 100% reduction (actual change is dependent on a means-test)

Sheet Table 2.13
A1: Table 2.13: Number of dwellings in Receipt of Council Tax Discounts and Reductions at September from 2020-21 to 2024-25
A2: This worksheet contains one table. Please note the following:
A3: Some dwellings may be eligible for more than one type of support, in these cases, the dwelling will be counted under each type of support it is eligible for.
A4: It is not possible for some local authorities to separately identify Second Homes and Long Term Empty dwellings. For these authorities, the total number of Second Homes and Long Term Empty dwellings has been recorded under Second Homes.
A5: Source: CTaxbase and CTR Extract
A6: Return to Contents
A8: Type of Support | B8: 2020-21 | C8: 2021-22 | D8: 2022-23 | E8: 2023-24 | F8: 2024-25
A9: Disability reduction | B9: 14009 | C9: 13988 | D9: 14096 | E9: 14686 | F9: 15082
A10: Single Person Discount | B10: 1004557 | C10: 1025094 | D10: 1037962 | E10: 1048186 | F10: 1054874
A11: Second Homes | B11: 24466 | C11: 23890 | D11: 24287 | E11: 24061 | F11: 21606
A12: Empty Properties | B12: 47333 | C12: 43766 | D12: 44601 | E12: 46217 | F12: 43538
A13: Occupied entirely by disregarded adults | B13: 1500 | C13: 1460 | D13: 1434 | E13: 1462 | F13: 1495
A14: Dwellings not subject to discount | B14: 1445031 | C14: 1446423 | D14: 1454073 | E14: 1461802 | F14: 1480941
A15: Council Tax Reduction recipients | B15: 500620 | C15: 482060 | D15: 462200 | E15: 460750 | F15: 460680
A16: All chargeable dwellings | B16: 2522887 | C16: 2540633 | D16: 2562357 | E16: 2581728 | F16: 2602545

Sheet Table 2.14
A1: Table 2.14: NDR Contributable and Distributable Amounts from 2009-10 to 2024-25, £ millions
A2: This worksheet contains one table.
A3: Please note that the NDR Contributable Amounts reflect the final, audited income figures collected by local authorities. This is except for the 2022-23, 2023-24 and 2024-25 figures, which are the Notified (provisional outturn) figures as the audits are not yet finalised for all councils. They are net of reliefs paid by Scottish Government, but gross of all local reliefs and top-ups to discretionary amounts paid by councils themselves.
A4: Sources: NDRI Audited and Notified Returns, Local Government Finance Circulars.
A5: Return to Contents
A7: NDR Type | B7: 2009-10 | C7: 2010-11 | D7: 2011-12 | E7: 2012-13 | F7: 2013-14 | G7: 2014-15 | H7: 2015-16 | I7: 2016-17 | J7: 2017-18 | K7: 2018-19 | L7: 2019-20 | M7: 2020-21 | N7: 2021-22 | O7: 2022-23 | P7: 2023-24 | Q7: 2024-25
A8: NDR contributable amount | B8: 2009.8262 | C8: 2138.1625 | D8: 2251.0517 | E8: 2346.9152 | F8: 2366.8845 | G8: 2511.2896 | H8: 2578.7703 | I8: 2731.4814 | J8: 2762.2489 | K8: 2846.5466 | L8: 2752.8307 | M8: 1816.1203 | N8: 2108.1802 | O8: 2791.9627 | P8: 3033 | Q8: 3146.3172
A9: NDR distributable amount | B9: 2127 | C9: 2068 | D9: 2171 | E9: 2263 | F9: 2435 | G9: 2649.5 | H9: 2788.5 | I9: 2768.5 | J9: 2665.8 | K9: 2636 | L9: 2853 | M9: 1868.03 | N9: 2090 | O9: 2766 | P9: 3047 | Q9: 3068

Sheet Table 2.14a
A1: Table 2.14a: NDR Properties, Rateable Values, Contributable and Distributable Amounts for 2024-25
A2: This worksheet contains one table. Please note the following:
A3: Figures include rates bills for specific utilities which are collected by specified councils on behalf of all local authorities and appear on the valuation roll for those councils. These are:
A4: South Lanarkshire - Electricity; West Dunbartonshire - Gas; Fife - Water; Falkirk - Docks and Harbours; Highland - Railways; Renfrewshire - Telecommunications.
A5: The number of properties includes properties with a zero rateable value.
A6: NDR Contributable Amounts reflect the notified (provisional outturn) figures as audited figures are not yet finalised for all councils. They are net of reliefs paid by Scottish Government, but gross of all local reliefs and top-ups to discretionary amounts paid by councils themselves.
A7: NDR Distributable Amounts reflect the amounts distributed to local authorities as part of the GAE. It is based upon an estimate of the NDR income, including prior year adjustments. It is not guaranteed to match the contributable amount of income that year.
A8: Source: Scottish Assessors Valuation Roll, NDRI Notified Returns, Local Government Finance Circular 2/2024.
A9: Return to Contents | D9: Revised 04/02/2026 | E9: Revised 04/02/2026
A11: Local Authority | B11: Number of properties at 1 April 2024 | C11: Rateable value at 1 April 2024, £ thousands | D11: NDR contributable amount 2024-25, £ thousands | E11: NDR distributable amount 2024-25, £ thousands
A12: Aberdeen City | B12: 9903 | C12: 484807.25 | D12: 205176.52 | E12: 208768
A13: Aberdeenshire | B13: 14270 | C13: 305200.36 | D13: 132333.32 | E13: 131630
A14: Angus | B14: 5619 | C14: 87563.665 | D14: 29970.205 | E14: 29304
A15: Argyll and Bute | B15: 9644 | C15: 133271.57 | D15: 47563.666 | E15: 41334
A16: City of Edinburgh | B16: 22910 | C16: 990250.01 | D16: 402779.27 | E16: 407645
A17: Clackmannanshire | B17: 1728 | C17: 46631.31 | D17: 18684.238 | E17: 19659
A18: Dumfries and Galloway | B18: 10397 | C18: 158136.86 | D18: 65300.066 | E18: 63708
A19: Dundee City | B19: 6285 | C19: 193360.32 | D19: 67243.812 | E19: 73695
A20: East Ayrshire | B20: 4760 | C20: 89088.511 | D20: 32659.62 | E20: 33530
A21: East Dunbartonshire | B21: 2439 | C21: 74075.7 | D21: 25907.167 | E21: 25901
A22: East Lothian | B22: 3800 | C22: 141744.1 | D22: 61978.992 | E22: 59925
A23: East Renfrewshire | B23: 1945 | C23: 44533.273 | D23: 15922.355 | E23: 15941
... A44: Scotland | B44: 259680 | C44: 7693240.4 | D44: 3146317.2 | E44: 3068000

Sheet Table 2.14b
A1: Table 2.14b: NDR Properties and Rateable Values at 1 April 2025
A2: This worksheet contains one table. Please note the following:
A3: Figures include rateable values for specific utilities which are collected by specified councils on behalf of all local authorities and appear on the valuation roll for those councils. These are:
A4: South Lanarkshire - Electricity; West Dunbartonshire - Gas; Fife - Water; Falkirk - Docks and Harbours; Highland - Railways; Renfrewshire - Telecommunications.
A5: The number of properties includes properties with a zero rateable value.
A6: Source: Scottish Assessors Valuation Roll
A7: Return to Contents
A9: Local Authority | B9: Number of properties | C9: Rateable value, £ thousands
A10: Aberdeen City | B10: 9913 | C10: 470815.34
A11: Aberdeenshire | B11: 14244 | C11: 303639.63
A12: Angus | B12: 5654 | C12: 87097.695
A13: Argyll and Bute | B13: 9230 | C13: 134629.81
A14: City of Edinburgh | B14: 22602 | C14: 973230.14
A15: Clackmannanshire | B15: 1743 | C15: 47029.26
A16: Dumfries and Galloway | B16: 10418 | C16: 157884.62
A17: Dundee City | B17: 6283 | C17: 187740.51
A18: East Ayrshire | B18: 5068 | C18: 89749.121
A19: East Dunbartonshire | B19: 2454 | C19: 72529.59
A20: East Lothian | B20: 3815 | C20: 140904.44
A21: East Renfrewshire | B21: 2016 | C21: 45152.684
... A42: Scotland | B42: 259790 | C42: 7610629.8

Sheet Table 2.15
A1: Table 2.15: NDR Properties at 1 April 2024 by Classification
A2: This worksheet contains one table. Please note that the number of properties includes properties with a zero rateable value.
A3: Source: Scottish Assessors Valuation Roll
A4: Return to Contents
A6: Classification | B6: Number of properties | C6: Proportion of properties on valuation roll | D6: Rateable value, £ thousands | E6: Proportion of rateable value on valuation roll
A7: Shops | B7: 54827 | C7: 0.21113293 | D7: 1454663.6 | E7: 0.18908334
A8: Public houses and restaurants | B8: 3597 | C8: 0.013851664 | D8: 120690.23 | E8: 0.015687828
A9: Offices | B9: 44428 | C9: 0.17108749 | D9: 1031388.8 | E9: 0.13406428
A10: Hotels | B10: 5118 | C10: 0.019708872 | D10: 289932.93 | E10: 0.037686711
A11: Industrial subjects | B11: 60528 | C11: 0.23308688 | D11: 1406556.2 | E11: 0.18283013
A12: Leisure, entertainment, caravans, etc. | B12: 26923 | C12: 0.1036776 | D12: 347775.94 | E12: 0.045205391
A13: Garages and petrol stations | B13: 3874 | C13: 0.014918361 | D13: 77939.577 | E13: 0.010130917
A14: Cultural | B14: 1356 | C14: 0.0052218115 | D14: 57171.769 | E14: 0.0074314289
A15: Sporting subjects | B15: 12984 | C15: 0.05 | D15: 41373.454 | E15: 0.0053778969
A16: Education and training | B16: 3599 | C16: 0.013859365 | D16: 631248.49 | E16: 0.082052355
A17: Public service subjects | B17: 9344 | C17: 0.035982748 | D17: 361545.49 | E17: 0.046995216
A18: Communications | B18: 360 | C18: 0.0013863216 | D18: 28445.5 | E18: 0.0036974667
... A27: All Non-Domestic Properties | B27: 259680 | C27: 1 | D27: 7693240.4 | E27: 1

Sheet Table 2.15a
A1: Table 2.15a: NDR Properties at 1 April 2025 by Classification
A2: This worksheet contains one table. Please note that the number of properties includes properties with a zero rateable value.
A3: Source: Scottish Assessors Valuation Roll
A4: Return to Contents
A6: Classification | B6: Number of properties | C6: Proportion of properties on valuation roll | D6: Rateable value, £ thousands | E6: Proportion of rateable value on valuation roll
A7: Shops | B7: 54745 | C7: 0.2107279 | D7: 1413976.4 | E7: 0.18578967
A8: Public houses and restaurants | B8: 3558 | C8: 0.013695677 | D8: 118201.68 | E8: 0.01553113
A9: Offices | B9: 44284 | C9: 0.17046076 | D9: 1003123.5 | E9: 0.13180558
A10: Hotels | B10: 4943 | C10: 0.019026906 | D10: 285200.34 | E10: 0.037473948
A11: Industrial subjects | B11: 61464 | C11: 0.23659109 | D11: 1402956 | E11: 0.18434164
A12: Leisure, entertainment, caravans, etc. | B12: 26388 | C12: 0.10157435 | D12: 342097.37 | E12: 0.044949942
A13: Garages and petrol stations | B13: 3880 | C13: 0.01493514 | D13: 80256.017 | E13: 0.010545253
A14: Cultural | B14: 1361 | C14: 0.0052388468 | D14: 57311.569 | E14: 0.0075304633
A15: Sporting subjects | B15: 12965 | C15: 0.049905693 | D15: 41593.423 | E15: 0.0054651749
A16: Education and training | B16: 3617 | C16: 0.013922784 | D16: 631343.56 | E16: 0.082955494
A17: Public service subjects | B17: 9337 | C17: 0.035940567 | D17: 362965.34 | E17: 0.047691893
A18: Communications | B18: 348 | C18: 0.0013395435 | D18: 28546.15 | E18: 0.0037508262
... A27: All Non-Domestic Properties | B27: 259790 | C27: 1 | D27: 7610629.8 | E27: 1
B29: =SUM(B7:B26)-B27 -> 0 | C29: =SUM(C7:C26)-C27 -> 0 | D29: =SUM(D7:D26)-D27 -> 0 | E29: =SUM(E7:E26)-E27 -> 0

Sheet Chart 2.10
A1: Chart 2.10: Proportion of NDR Properties at 1 April 2024 by Local Authority and Rateable Value Band
A2: This worksheet contains one table and one chart. Please note the following:
A3: The number of properties includes properties with a zero rateable value.
A5: Source: Scottish Assessors Valuation Roll
A6: Return to Contents
A8: Local Authority | B8: Number with RV £20,000 or lower | C8: Number with RV between £20,001 and £51,000 | D8: Number with RV between £51,001 and £100,000 | E8: Number with RV higher than £100,000 | F8: Total number of properties | G8: Proportion with RV £20,000 or lower | H8: Proportion with RV between £20,001 and £51,000 | I8: Proportion with RV £51,001 or higher
A9: Argyll and Bute | B9: 8797 | C9: 535 | D9: 149 | E9: 163 | F9: 9644 | G9: 0.91217337 | H9: 0.055474907 | I9: 0.032351721
A10: Na h-Eileanan Siar | B10: 2564 | C10: 155 | D10: 54 | E10: 46 | F10: 2819 | G10: 0.90954239 | H10: 0.054984037 | I10: 0.035473572
A11: Scottish Borders | B11: 8199 | C11: 506 | D11: 183 | E11: 171 | F11: 9059 | G11: 0.90506678 | H11: 0.055856055 | I11: 0.039077161
A12: Orkney Islands | B12: 2364 | C12: 184 | D12: 36 | E12: 33 | F12: 2617 | G12: 0.90332442 | H12: 0.070309515 | I12: 0.026366068
A13: Dumfries and Galloway | B13: 9374 | C13: 598 | D13: 221 | E13: 204 | F13: 10397 | G13: 0.90160623 | H13: 0.057516591 | I13: 0.040877176
A14: Angus | B14: 4970 | C14: 388 | D14: 117 | E14: 144 | F14: 5619 | G14: 0.88449902 | H14: 0.069051433 | I14: 0.046449546
A15: Shetland Islands | B15: 2090 | C15: 165 | D15: 56 | E15: 62 | F15: 2373 | G15: 0.88074168 | H15: 0.069532238 | I15: 0.049726085
A16: Perth and Kinross | B16: 8608 | C16: 649 | D16: 269 | E16: 285 | F16: 9811 | G16: 0.87738253 | H16: 0.06615024 | I16: 0.056467231
A17: Moray | B17: 4822 | C17: 401 | D17: 152 | E17: 206 | F17: 5581 | G17: 0.86400287 | H17: 0.071850923 | I17: 0.06414621
A18: Highland | B18: 17084 | C18: 1481 | D18: 591 | E18: 632 | F18: 19788 | G18: 0.86335153 | H18: 0.074843339 | I18: 0.061805134
A19: East Ayrshire | B19: 4101 | C19: 360 | D19: 148 | E19: 151 | F19: 4760 | G19: 0.86155462 | H19: 0.075630252 | I19: 0.062815126
A20: Renfrewshire | B20: 8489 | C20: 772 | D20: 325 | E20: 377 | F20: 9963 | G20: 0.85205259 | H20: 0.077486701 | I20: 0.070460705
... A41: Aberdeen City | B41: 6422 | C41: 1631 | D41: 841 | E41: 1009 | F41: 9903 | G41: 0.64849036 | H41: 0.16469757 | I41: 0.18681208
U42: `

Sheet Chart 2.10a
A1: Chart 2.10a: Proportion of NDR Properties at 1 April 2025 by Local Authority and Rateable Value Band
A2: This worksheet contains one table and one chart. Please note the following:
A3: The number of properties includes properties with a zero rateable value.
A5: Source: Scottish Assessors Valuation Roll
A6: Return to Contents
A8: Local Authority | B8: Number with RV £20,000 or lower | C8: Number with RV between £20,001 and £51,000 | D8: Number with RV between £51,001 and £100,000 | E8: Number with RV higher than £100,000 | F8: Total number of properties | G8: Proportion with RV £20,000 or lower | H8: Proportion with RV between £20,001 and £51,000 | I8: Proportion with RV £51,001 or higher
A9: Argyll and Bute | B9: 8397 | C9: 520 | D9: 151 | E9: 162 | F9: 9230 | G9: 0.90975081 | H9: 0.056338028 | I9: 0.033911159
A10: Na h-Eileanan Siar | B10: 2480 | C10: 156 | D10: 52 | E10: 46 | F10: 2734 | G10: 0.90709583 | H10: 0.057059254 | I10: 0.035844916
A11: Orkney Islands | B11: 2402 | C11: 183 | D11: 36 | E11: 33 | F11: 2654 | G11: 0.90504898 | H11: 0.068952524 | I11: 0.025998493
A12: Scottish Borders | B12: 8095 | C12: 510 | D12: 181 | E12: 171 | F12: 8957 | G12: 0.90376242 | H12: 0.056938707 | I12: 0.039298872
A13: Dumfries and Galloway | B13: 9400 | C13: 595 | D13: 214 | E13: 209 | F13: 10418 | G13: 0.90228451 | H13: 0.05711269 | I13: 0.040602803
A14: Angus | B14: 5000 | C14: 390 | D14: 118 | E14: 146 | F14: 5654 | G14: 0.88432968 | H14: 0.068977715 | I14: 0.046692607
A15: Shetland Islands | B15: 2096 | C15: 166 | D15: 54 | E15: 61 | F15: 2377 | G15: 0.88178376 | H15: 0.069835928 | I15: 0.048380311
A16: Perth and Kinross | B16: 8631 | C16: 660 | D16: 261 | E16: 281 | F16: 9833 | G16: 0.87775857 | H16: 0.067120919 | I16: 0.055120513
A17: East Ayrshire | B17: 4412 | C17: 366 | D17: 141 | E17: 149 | F17: 5068 | G17: 0.87056038 | H17: 0.072217837 | I17: 0.057221784
A18: Highland | B18: 16977 | C18: 1481 | D18: 578 | E18: 626 | F18: 19662 | G18: 0.86344217 | H18: 0.075322958 | I18: 0.061234869
A19: Moray | B19: 4767 | C19: 399 | D19: 153 | E19: 207 | F19: 5526 | G19: 0.86264929 | H19: 0.072204126 | I19: 0.06514658
A20: Renfrewshire | B20: 8601 | C20: 756 | D20: 316 | E20: 376 | F20: 10049 | G20: 0.85590606 | H20: 0.075231366 | I20: 0.068862573
... A41: Aberdeen City | B41: 6500 | C41: 1603 | D41: 822 | E41: 988 | F41: 9913 | G41: 0.65570463 | H41: 0.16170685 | I41: 0.18258852

Sheet Table 2.16
A1: Table 2.16: NDR Income, Total Rateable Values and Rates from 2009-10 to 2024-25
A2: This worksheet contains one table. Please note the following:
A3: Revaluations occurred in 2010, 2017 and 2023
A4: NDRI figures are the NDR Contributable Amounts, and reflect the final, audited income figures collected by local authorities, except for 2022-23, 2023-24 and 2024-25 which are the Notified (provisional outturn) figures as the audits are not yet finalised for all councils.
A5: They are net of reliefs paid by Scottish Government, but gross of all local reliefs and top-ups to discretionary amounts paid by councils themselves.
A6: “n/a” indicates years prior to the introduction of the Intermediate Property Rate (IPR) where there were no IPR rates or thresholds. The Higher Property Rate (HPR) - formerly the Large Business Supplement (LBS) - and the IPR
A7: are applied for properties with an rateable value over the HPR / LBS or IPR threshold.
A8: Source: NDRI Audited Returns, NDRI Notified Return, and Scottish Assessors Valuation Roll.
A9: Return to Contents
A11: Category | B11: 2009-10 | C11: 2010-11 | D11: 2011-12 | E11: 2012-13 | F11: 2013-14 | G11: 2014-15 | H11: 2015-16 | I11: 2016-17 | J11: 2017-18 | K11: 2018-19 | L11: 2019-20 | M11: 2020-21 | N11: 2021-22 | O11: 2022-23 | P11: 2023-24 | Q11: 2024-25
A12: NDRI, £ millions | B12: 2009.8262 | C12: 2138.1625 | D12: 2251.0517 | E12: 2346.9152 | F12: 2366.8845 | G12: 2511.2896 | H12: 2578.7703 | I12: 2731.4814 | J12: 2762.2489 | K12: 2846.5466 | L12: 2761.496 | M12: 1816.1203 | N12: 2108.1802 | O12: 2791.9627 | P12: 3033 | Q12: 3146.3172
A13: Total Rateable Value at 1 April, £ millions | B13: 5299 | C13: 6612 | D13: 6677.7613 | E13: 6717.6069 | F13: 6716.2993 | G13: 6680.715 | H13: 6718.7051 | I13: 6795.9583 | J13: 7357.6752 | K13: 7438.5619 | L13: 7462.137 | M13: 7386.437 | N13: 7325.1309 | O13: 7296.1475 | P13: 7696.884 | Q13: 7693.2404
A14: Basic Property Rate, pence | B14: 48.1 | C14: 40.7 | D14: 42.6 | E14: 45 | F14: 46.2 | G14: 47.1 | H14: 48 | I14: 48.4 | J14: 46.6 | K14: 48 | L14: 49 | M14: 49.8 | N14: 49 | O14: 49.8 | P14: 49.8 | Q14: 49.8
A15: Intermediate Property Rate (IPR), pence | B15: n/a | C15: n/a | D15: n/a | E15: n/a | F15: n/a | G15: n/a | H15: n/a | I15: n/a | J15: n/a | K15: n/a | L15: n/a | M15: 51.1 | N15: 50.3 | O15: 51.1 | P15: 51.1 | Q15: 54.5
A16: IPR threshold, £ | B16: n/a | C16: n/a | D16: n/a | E16: n/a | F16: n/a | G16: n/a | H16: n/a | I16: n/a | J16: n/a | K16: n/a | L16: n/a | M16: 51000 | N16: 51000 | O16: 51000 | P16: 51000 | Q16: 51000
A17: LBS / Higher Property Rate (HPR), pence | B17: 48.5 | C17: 41.4 | D17: 43.3 | E17: 45.8 | F17: 47.1 | G17: 48.2 | H17: 49.3 | I17: 51 | J17: 49.2 | K17: 50.6 | L17: 51.6 | M17: 52.4 | N17: 51.6 | O17: 52.4 | P17: 52.4 | Q17: 55.9
A18: LBS / HPR threshold, £ | B18: 29000 | C18: 35000 | D18: 35000 | E18: 35000 | F18: 35000 | G18: 35000 | H18: 35000 | I18: 35000 | J18: 51000 | K18: 51000 | L18: 51000 | M18: 95000 | N18: 95000 | O18: 95000 | P18: 100000 | Q18: 100000

Sheet Table 2.17
A1: Table 2.17: Amount of NDR Relief Provided from 2009-10 to 2024-25 by Relief Type, £ thousands
A2: This worksheet contains one table. Please note the following:
A3: Figures include mandatory and discretionary elements of relief where applicable, but exclude backdated payments of relief and exclude councils own contributions to reliefs.
A4: 'Other' includes Hardship Relief; Enterprise Areas; District Heating Relief; Mobile Mast Relief (from 2018-19); New Fibre Relief (from 2018-19); Lighthouse Relief (from 2019-20, previously recorded as a deduction).
A5: Empty Property Relief figures for 2018-19 to 2020-21 in this publication differ from previous publications, because an error in reporting for one council was discovered and figures have now been amended. Empty Property Relief was devolved to councils and became a local relief from April 2023.
A6: Retail Hospitality, Leisure and Aviation Relief was introduced in 2020-21. It continued in 2021-22 and became Retail, Hospitality and Leisure Relief in 2022-23.
A7: Revaluation Transitional Relief includes both 2017 Transitional Reliefs and 2023 General Transitional Relief.
A8: "n/a" is used for years prior to a relief being introduced or after a relief is discontinued.
A9: Source: NDRI Audited returns for all years except 2022-23, 2023-24 and 2024-25 where the NDRI Notified Returns have been used.
A10: Return to Contents
A12: Relief Type | B12: 2009-10 | C12: 2010-11 | D12: 2011-12 | E12: 2012-13 | F12: 2013-14 | G12: 2014-15 | H12: 2015-16 | I12: 2016-17 | J12: 2017-18 | K12: 2018-19 | L12: 2019-20 | M12: 2020-21 | N12: 2021-22 | O12: 2022-23 | P12: 2023-24 | Q12: 2024-25
A13: Empty Property Relief | B13: 153361.5 | C13: 145936.26 | D13: 157862.01 | E13: 169133.52 | F13: 146496.06 | G13: 140961.74 | H13: 141603.6 | I13: 93681.579 | J13: 93987.518 | K13: 92903.733 | L13: 87500.257 | M13: 78670.233 | N13: 88070.213 | O13: 95471.486 | P13: n/a | Q13: n/a
A14: Charity Relief | B14: 122131.68 | C14: 136731.02 | D14: 151275.85 | E14: 164978.76 | F14: 173623.41 | G14: 181242.06 | H14: 189311.55 | I14: 201214.57 | J14: 214418.31 | K14: 218977.14 | L14: 224813.5 | M14: 223189.29 | N14: 214027.8 | O14: 215899.86 | P14: 231026.23 | Q14: 247224.65
A15: Sports Club Relief | B15: 11604.107 | C15: 11475.897 | D15: 12059.188 | E15: 12431.067 | F15: 12910.553 | G15: 13487.11 | H15: 13851.85 | I15: 13851.228 | J15: 13619.52 | K15: 15738.587 | L15: 15747.405 | M15: 14783.4 | N15: 13140.41 | O15: 14717.43 | P15: 16082.067 | Q15: 16763.418
A16: Disabled Rates Relief | B16: 45483.683 | C16: 51900.541 | D16: 54371.618 | E16: 57579.618 | F16: 58299.066 | G16: 59647.898 | H16: 60599.015 | I16: 61497.941 | J16: 61511.114 | K16: 64354.254 | L16: 64777.519 | M16: 64265.624 | N16: 63810.32 | O16: 63459.067 | P16: 68300.428 | Q16: 72363
A17: Small Business Bonus Scheme | B17: 108419.96 | C17: 123259.07 | D17: 134718.62 | E17: 150195.81 | F17: 161001.63 | G17: 170634.89 | H17: 179543.77 | I17: 187029.23 | J17: 240663.34 | K17: 261684.37 | L17: 278054.58 | M17: 279441.05 | N17: 271176.41 | O17: 281542.04 | P17: 231149.53 | Q17: 250548.07
A18: Religious Exemptions | B18: 20218.468 | C18: 24016.4 | D18: 22960.421 | E18: 24573.044 | F18: 25205.491 | G18: 26113.328 | H18: 26624.951 | I18: 27014.167 | J18: 26303.134 | K18: 27128.619 | L18: 27580.986 | M18: 27402.409 | N18: 27480.726 | O18: 27811.618 | P18: 29631.994 | Q18: 30445.831
A19: Rural Relief | B19: 3918.0162 | C19: 4128.7974 | D19: 4218.322 | E19: 4305.1853 | F19: 4323.235 | G19: 4243.905 | H19: 4234.707 | I19: 4114.043 | J19: 3987.631 | K19: 3946.024 | L19: 3914.372 | M19: 3821.743 | N19: 3774.9546 | O19: 3888.439 | P19: 3530.747 | Q19: 3533.1936
A20: Renewable Energy Relief | B20: n/a | C20: 3560.34 | D20: 4126.076 | E20: 4811.317 | F20: 7332.54 | G20: 9280.142 | H20: 9544.734 | I20: 647.454 | J20: 1278.952 | K20: 7399.443 | L20: 7265.865 | M20: 6438.512 | N20: 8009.8886 | O20: 8062.158 | P20: 8499.685 | Q20: 10155.429
A21: New Start Relief | B21: n/a | C21: n/a | D21: n/a | E21: n/a | F21: 130.061 | G21: 483.571 | H21: 187.743 | I21: 397.851 | J21: 497.149 | K21: 447.49 | L21: 172.046 | M21: n/a | N21: n/a | O21: n/a | P21: n/a | Q21: n/a
A22: Fresh Start Relief | B22: n/a | C22: n/a | D22: n/a | E22: n/a | F22: 188.525 | G22: 536.074 | H22: 573.273 | I22: 606.651 | J22: 436.282 | K22: 1690.004 | L22: 3811.793 | M22: 2321.383 | N22: 4085.6989 | O22: 5969.71 | P22: 4653.039 | Q22: 8577.873
A23: Revaluation Transitional Relief | B23: n/a | C23: n/a | D23: n/a | E23: n/a | F23: n/a | G23: n/a | H23: n/a | I23: n/a | J23: 26330.379 | K23: 11899.24 | L23: 5243.24 | M23: 36.426 | N23: 12.684 | O23: 168.824 | P23: 68277.806 | Q23: 12923.002
A24: Day Nursery Relief | B24: n/a | C24: n/a | D24: n/a | E24: n/a | F24: n/a | G24: n/a | H24: n/a | I24: n/a | J24: n/a | K24: 9604.384 | L24: 9788.08 | M24: 9600.792 | N24: 9761.5473 | O24: 10095.389 | P24: 9836.2 | Q24: 11430.682
A25: BGA - Unoccupied New Build | B25: n/a | C25: n/a | D25: n/a | E25: n/a | F25: n/a | G25: n/a | H25: n/a | I25: n/a | J25: n/a | K25: 5660.139 | L25: 3468.243 | M25: 2972.683 | N25: 2303.665 | O25: 1904.807 | P25: 3775.452 | Q25: 989.572
A26: BGA - New Occupied and Improved | B26: n/a | C26: n/a | D26: n/a | E26: n/a | F26: n/a | G26: n/a | H26: n/a | I26: n/a | J26: n/a | K26: 11206.546 | L26: 31712.985 | M26: 10519.47 | N26: 12978.066 | O26: 22415.815 | P26: 21161.373 | Q26: 27237.286
A27: Retail, Hospitality, Leisure (and Aviation) Relief | B27: n/a | C27: n/a | D27: n/a | E27: n/a | F27: n/a | G27: n/a | H27: n/a | I27: n/a | J27: n/a | K27: n/a | L27: n/a | M27: 941228.56 | N27: 640500.75 | O27: 27714.761 | P27: n/a | Q27: n/a
A28: Small Business Transitional Relief | B28: n/a | C28: n/a | D28: n/a | E28: n/a | F28: n/a | G28: n/a | H28: n/a | I28: n/a | J28: n/a | K28: n/a | L28: n/a | M28: n/a | N28: n/a | O28: n/a | P28: 21740.251 | Q28: 19413.714
A29: Parks Transitional Relief | B29: n/a | C29: n/a | D29: n/a | E29: n/a | F29: n/a | G29: n/a | H29: n/a | I29: n/a | J29: n/a | K29: n/a | L29: n/a | M29: n/a | N29: n/a | O29: n/a | P29: 1502.279 | Q29: 876.63
A30: Islands Hospitality Relief | B30: n/a | C30: n/a | D30: n/a | E30: n/a | F30: n/a | G30: n/a | H30: n/a | I30: n/a | J30: n/a | K30: n/a | L30: n/a | M30: n/a | N30: n/a | O30: n/a | P30: n/a | Q30: 4816.9833
A31: 1.6% Universal Relief | B31: n/a | C31: n/a | D31: n/a | E31: n/a | F31: n/a | G31: n/a | H31: n/a | I31: n/a | J31: n/a | K31: n/a | L31: n/a | M31: 60062.482 | N31: n/a | O31: n/a | P31: n/a | Q31: n/a
A32: Other | B32: 19.388 | C32: 4.365 | D32: 42.697 | E32: 9.715 | F32: 63.32 | G32: 221.331 | H32: 422.069 | I32: 729.698 | J32: 1103.733 | K32: 1161.288 | L32: 1210.894 | M32: 1608.818 | N32: 1568.4135 | O32: 2276.447 | P32: 2490.406 | Q32: 7188.8876
A33: Total Relief Provided | B33: 465156.8 | C33: 501012.69 | D33: 541634.8 | E33: 588018.03 | F33: 589573.89 | G33: 606852.06 | H33: 626497.25 | I33: 590784.41 | J33: 684137.06 | K33: 733801.26 | L33: 765061.76 | M33: 1726362.9 | N33: 1360701.5 | O33: 781397.85 | P33: 721657.49 | Q33: 724488.22

Sheet Table 2.17a
A1: Table 2.17a: Amount of NDR Relief Provided in 2024-25 by Relief Type and Local Authority, £ thousands
A2: This worksheet contains one table. Please note the following:
A3: Figures include mandatory and discretionary elements of relief where applicable, but exclude backdated payments of relief and exclude councils own contributions to reliefs.
A4: Please note that NDR reliefs reflect the notified income figures collected by local authorities, because the audited income figures are not yet finalised for all councils.
A5: 'Other' includes Hardship Relief; Enterprise Areas; District Heating Relief; Mobile Mast Relief; New Fibre Relief; Lighthouse Relief.
A6: The table makes use of following acronym: 'SBBS' is Small Business Bonus Scheme.
A7: Source: NDRI Notified Returns
A8: Return to Contents
A10: Local Authority | B10: Charity Relief | C10: Sports Club Relief | D10: Disabled Rates Relief | E10: SBBS | F10: Religious Exemptions | G10: Rural Relief | H10: Renewable Energy Relief | I10: Fresh Start Relief | J10: Revaluation Transitional Relief | K10: Day Nursery Relief | L10: BGA - Unoccupied New Build | M10: BGA - New Occupied & Improved | N10: Small Business Transitional Relief | O10: Parks Transitional Relief | P10: Islands Hospitality Relief | Q10: Other | R10: All Reliefs
A11: Aberdeen | B11: 11961.108 | C11: 2244.832 | D11: 2640.023 | E11: 6295.399 | F11: 1669.079 | G11: 0 | H11: 20.667 | I11: 355.682 | J11: 385.144 | K11: 520.698 | L11: 309.93 | M11: 1068.783 | N11: 122.638 | O11: 0 | P11: 0 | Q11: 152.638 | R11: 27746.621
A12: Aberdeenshire | B12: 3434.425 | C12: 1235.557 | D12: 2389.176 | E12: 12522.098 | F12: 1528.921 | G12: 1224.242 | H12: 294.377 | I12: 526.325 | J12: 408.366 | K12: 520.267 | L12: 215.299 | M12: 1051.129 | N12: 1006.526 | O12: 30.921 | P12: 0 | Q12: 21.032 | R12: 26408.661
A13: Angus | B13: 3754.234 | C13: 377.47 | D13: 1305.48 | E13: 6117.505 | F13: 532.053 | G13: 40.89 | H13: 64.152 | I13: 37.159 | J13: 265.47 | K13: 157.719 | L13: 0 | M13: 1723.909 | N13: 149.621 | O13: 0 | P13: 0 | Q13: 9.407 | R13: 14535.069
A14: Argyll & Bute | B14: 3464.471 | C14: 177.663 | D14: 489.31 | E14: 8146.333 | F14: 536.881 | G14: 164.024 | H14: 1657.826 | I14: 24.667 | J14: 1576.897 | K14: 82.407 | L14: 0 | M14: 46.052 | N14: 831.38 | O14: 12.505 | P14: 1365.236 | Q14: 128.1 | R14: 18703.752
A15: Clackmannanshire | B15: 937.771 | C15: 115.74 | D15: 466.402 | E15: 1749.941 | F15: 210.992 | G15: 5.83 | H15: 6.798 | I15: 11.623 | J15: 49.074 | K15: 120.217 | L15: 0 | M15: 490.995 | N15: 61.763 | O15: 0 | P15: 0 | Q15: 0 | R15: 4227.146
A16: Dumfries & Galloway | B16: 2567.254 | C16: 399.975 | D16: 1629.402 | E16: 9742.649 | F16: 641.176 | G16: 158.43 | H16: 326.826 | I16: 104.192 | J16: 218.068 | K16: 134.144 | L16: 0 | M16: 122.251 | N16: 370.613 | O16: 0 | P16: 0 | Q16: 41.657 | R16: 16456.637
A17: Dundee City | B17: 14619.682 | C17: 168.605 | D17: 2561.499 | E17: 6704.71 | F17: 702.91 | G17: 0 | H17: 0 | I17: 346.939 | J17: 612.444 | K17: 401.138 | L17: 9.316 | M17: 740.537 | N17: 477.559 | O17: 22.204 | P17: 0 | Q17: 0 | R17: 27367.543
A18: East Ayrshire | B18: 3787.409 | C18: 149.158 | D18: 1378.376 | E18: 4932.46 | F18: 495.134 | G18: 2.316 | H18: 78.489 | I18: 43 | J18: 278.71 | K18: 326.924 | L18: 0 | M18: 560.849 | N18: 0 | O18: 0 | P18: 0 | Q18: 0.49 | R18: 12033.315
A19: East Dunbartonshire | B19: 3947.712 | C19: 451.242 | D19: 1352.906 | E19: 3301.002 | F19: 565.787 | G19: 0 | H19: 0 | I19: 55.708 | J19: 57.371 | K19: 249.053 | L19: 0 | M19: 97.619 | N19: 301.429 | O19: 16.718 | P19: 0 | Q19: 0 | R19: 10396.547
A20: East Lothian | B20: 3336.813 | C20: 1156.9 | D20: 1803.158 | E20: 4857.783 | F20: 527.999 | G20: 41.089 | H20: 54.523 | I20: 59.152 | J20: 307.44 | K20: 208.967 | L20: 0 | M20: 356.301 | N20: 317.549 | O20: 0 | P20: 0 | Q20: 5.812 | R20: 13033.486
